<?xml version="1.0"?>
<robot>
 <gazebo reference="base_link">
    <material>Gazebo/Red</material>

      <inertial>
        <mass>14.0</mass>
        <inertia>          
          <!-- http://en.wikipedia.org/wiki/List_of_moment_of_inertia_tensors
          MATLAB:
          m=14; h=0.19; w=0.4; d=0.5; 
          ixx = 1/12*m*(h^2+d^2)
          iyy = 1/12*m*(w^2+d^2) 
          izz = 1/12*m*(h^2+d^2) 
          -->
          <ixx>0.3338</ixx>
          <ixy>0.0</ixy>
          <ixz>0.0</ixz>
          <iyy>0.4783</iyy>
          <iyz>0.0</iyz>
          <izz>0.3338</izz>
        </inertia>
      </inertial>
      <collision name="collision">
        <geometry>
          <box>
            <size>0.501 0.400 0.19</size>
          </box>
        </geometry>
      </collision>
      <visual name="visual">
        <geometry>
          <mesh>
            <uri>model://pioneer3at/meshes/chassis.dae</uri>
          </mesh>
        </geometry>
      </visual>
    </gazebo>
    <gazebo reference="p3at_front_right_wheel">
      <pose>0.125 -0.201 -0.06 1.5707 0 0</pose>
	    <material>Gazebo/Black</material>
      <collision name="collision">
        <geometry>
          <cylinder>
            <radius>0.110</radius>
            <length>0.075</length>
          </cylinder>
        </geometry>
        <surface>
          <friction>
            <ode>
              <mu>1</mu>
              <mu2>1</mu2>
              <slip1>0.5</slip1>
              <slip2>0</slip2>
            </ode>
          </friction>
        </surface>
      </collision>
      <visual name="visual">
        <geometry>
          <mesh>
            <uri>model://pioneer3at/meshes/wheel.dae</uri>
          </mesh>
        </geometry>
      </visual>
    
 </gazebo>
 <gazebo reference="p3at_front_left_wheel">
      <pose>0.125 0.201 -0.06 1.5707 0 0</pose>
	<material>Gazebo/Black</material>
      <collision name="collision">
        <geometry>
          <cylinder>
            <radius>0.110</radius>
            <length>0.075</length>
          </cylinder>
        </geometry>
        <surface>
          <friction>
            <ode>
              <mu>1</mu>
              <mu2>1</mu2>
              <slip1>0.5</slip1>
              <slip2>0</slip2>
            </ode>
          </friction>
        </surface>
      </collision>
      <visual name="visual">
        <geometry>
          <mesh>
            <uri>model://pioneer3at/meshes/wheel.dae</uri>
          </mesh>
        </geometry>
      </visual>
    
 </gazebo>
 <gazebo reference="p3at_back_right_wheel">
      <pose>-0.125 -0.201 -0.06 1.5707 0 0</pose>
	<material>Gazebo/Black</material>      
	<collision name="collision">
        <geometry>
          <cylinder>
            <radius>0.110</radius>
            <length>0.075</length>
          </cylinder>
        </geometry>
        <surface>
          <friction>
            <ode>
              <mu>1</mu>
              <mu2>1</mu2>
              <slip1>0.5</slip1>
              <slip2>0</slip2>
            </ode>
          </friction>
        </surface>
      </collision>
      <visual name="visual">
        <geometry>
          <mesh>
            <uri>model://pioneer3at/meshes/wheel.dae</uri>
          </mesh>
        </geometry>
      </visual>
 </gazebo>   

 <gazebo reference="p3at_back_left_wheel">
      <pose>-0.125 0.201 -0.06 1.5707 0 0</pose>
	<material>Gazebo/Black</material>
      <collision name="collision">
        <geometry>
          <cylinder>
            <radius>0.110</radius>
            <length>0.075</length>
          </cylinder>
        </geometry>
        <surface>
          <friction>
            <ode>
              <mu>1</mu>
              <mu2>1</mu2>
              <slip1>0.5</slip1>
              <slip2>0</slip2>
            </ode>
          </friction>
        </surface>
      </collision>
      <visual name="visual">
        <geometry>
          <mesh>
            <uri>model://pioneer3at/meshes/wheel.dae</uri>
          </mesh>
        </geometry>
      </visual>
    
 </gazebo>
 <gazebo>
    <joint type="revolute" name="right_front">
      <pose>0 0 0 0 0 0</pose>
      <child>p3at_front_right_wheel</child>
      <parent>base_link</parent>
      <axis>
        <xyz>0 1 0</xyz>
      </axis>
    </joint>
 </gazebo>
 <gazebo>
    <joint type="revolute" name="right_rear">
      <pose>0 0 0 0 0 0</pose>
      <child>p3at_back_right_wheel</child>
      <parent>base_link</parent>
      <axis>
        <xyz>0 1 0</xyz>
      </axis>
    </joint>
 </gazebo>
 <gazebo>
    <joint type="revolute" name="left_front">
      <pose>0 0 0 0 0 0</pose>
      <child>p3at_front_left_wheel</child>
      <parent>base_link</parent>
      <axis>
        <xyz>0 1 0</xyz>
      </axis>
    </joint>
 </gazebo>
 <gazebo>
    <joint type="revolute" name="left_rear">
      <pose>0 0 0 0 0 0</pose>
      <child>p3at_back_left_wheel</child>
      <parent>base_link</parent>
      <axis>
        <xyz>0 1 0</xyz>
      </axis>
    </joint>
 </gazebo>
 <gazebo reference="top_plate">
	<material>Gazebo/Black</material>
 </gazebo>
</robot>
