<?xml version="1.0"?>

<robot name="pioneer3at" xmlns:xacro="http://www.ros.org/wiki/xacro"> 

<xacro:include filename="$(find p2os_urdf)/defs/pioneer3atomplex.gazebo" />


<!-- Chassis -->
	<link name="base_link">
		<inertial>
			<mass value="14"/>
			<origin xyz="0 0 0"/>
			<inertia ixx="0.3338" ixy="0" ixz="0"
				 iyy="0.4783" iyz="0"
				 izz="0.3338"/>
		</inertial>
		<visual name="base_visual">
			<origin xyz="0 0 0.082" rpy="0 0 0"/>
			<geometry name="pioneer_geom">
				<mesh filename="package://p2os_urdf/meshes/p3at_meshes/chassis.stl"/>
			</geometry>
			<material name="ChassisRed">
				<color rgba="0.851 0.0 0.0 1.0"/>
			</material>
		</visual>
		<collision>
	           <origin xyz="0 0 0.082" rpy="0 0 0"/>
				<geometry>
					<box size="0.501 0.400 0.19"/>
				</geometry>
		</collision>
	  </link>

<!-- Top -->
	<link name="top_plate">
		<inertial>
			<mass value="0.1"/>	
			<origin xyz="-0.025 0 -0.223"/>
			<inertia ixx="1" ixy="0" ixz="0"
				 iyy="1" iyz="0"
 				izz="1"/>
		</inertial>
		<visual name="base_visual">
			<origin xyz="0 0 0" rpy="0 0 0"/>
			<geometry name="pioneer_geom">
				<mesh filename="package://p2os_urdf/meshes/p3at_meshes/top.stl"/>
			</geometry>
			<material name="TopBlack">
					<color rgba="0.038 0.038 0.038 1.0"/>
			</material>
		</visual>
		<collision>
			<origin xyz="0 0 0" rpy="0 0 0"/>
			<geometry>
				<box size="0 0 0"/>
			</geometry>
		</collision>
	</link>

	<joint name="base_top_joint" type="fixed">
		<origin xyz="0.003 0 0.179" rpy="0 0 0"/>
		<parent link="base_link"/>
		<child link="top_plate"/>
	</joint>
<!-- Front + Back Sonar -->
	<link name="front_sonar">
		<inertial>
			<mass value="0"/>	
			<origin xyz="0 0 0"/>
			<inertia ixx="1" ixy="0" ixz="0"
				 iyy="1" iyz="0" izz="1"/>
		</inertial>
		<visual name="base_visual">
			<origin xyz="0 0 0" rpy="0 0 0"/>
			<geometry name="pioneer_geom">
				<mesh filename="package://p2os_urdf/meshes/p3at_meshes/front_sonar.stl"/>
			</geometry>
			<material name="SonarYellow">
				<color rgba="0.715 0.583 0.210 1.0"/>
			</material>
		</visual>
		<collision>
			<origin xyz="0 0 0" rpy="0 0 0"/>
			<geometry>
				<box size="0 0 0"/>
			</geometry>
		</collision>
	</link>

	<joint name="base_front_joint" type="fixed">
		<origin xyz="0.193 0 0.155" rpy="0 0 0"/>
		<parent link="base_link"/>
		<child link="front_sonar"/>
	</joint>

	<link name="back_sonar">
		<inertial>
			<mass value="0"/>	
			<origin xyz="0 0 0"/>
			<inertia ixx="1" ixy="0" ixz="0"
				 iyy="1" iyz="0" izz="1"/>
		</inertial>
		<visual name="base_visual">
			<origin xyz="0 0 0" rpy="0 0 0"/>
			<geometry name="pioneer_geom">
				<mesh filename="package://p2os_urdf/meshes/p3at_meshes/back_sonar.stl"/>
			</geometry>
			<material name="SonarYellow">
				<color rgba="0.715 0.583 0.210 1.0"/>
			</material>
		</visual>
		<collision>
			<origin xyz="0 0 0" rpy="0 0 0"/>
			<geometry>
				<box size="0 0 0"/>
			</geometry>
		</collision>
	</link>

	<joint name="base_back_joint" type="fixed">
		<origin xyz="-0.187 0 0.152" rpy="0 0 0"/>
		<parent link="base_link"/>
		<child link="back_sonar"/>
	</joint>

    <link name="right_front_wheel">
      <pose>0.125 -0.201 -0.06 1.5707 0 0</pose>
      <collision name="collision">
        <geometry>
          <cylinder>
            <radius>0.110</radius>
            <length>0.075</length>
          </cylinder>
        </geometry>
        <surface>
          <friction>
            <ode>
              <mu>1</mu>
              <mu2>1</mu2>
              <slip1>0.5</slip1>
              <slip2>0</slip2>
            </ode>
          </friction>
        </surface>
      </collision>
      <visual name="visual">
        <geometry>
	        <mesh filename="package://robotMeshes/meshes/wheel.dae"/>
          </geometry>
      </visual>
    </link>

    <link name="left_front_wheel">
      <pose>0.125 0.201 -0.06 1.5707 0 0</pose>
      <collision name="collision">
        <geometry>
          <cylinder>
            <radius>0.110</radius>
            <length>0.075</length>
          </cylinder>
        </geometry>
        <surface>
          <friction>
            <ode>
              <mu>1</mu>
              <mu2>1</mu2>
              <slip1>0.5</slip1>
              <slip2>0</slip2>
            </ode>
          </friction>
        </surface>
      </collision>
      <visual name="visual">
        <geometry>
          
           <mesh filename="package://robotMeshes/meshes/wheel.dae"/>
          
        </geometry>
      </visual>
    </link>

    <link name="right_rear_wheel">
      <pose>-0.125 -0.201 -0.06 1.5707 0 0</pose>
      <collision name="collision">
        <geometry>
          <cylinder>
            <radius>0.110</radius>
            <length>0.075</length>
          </cylinder>
        </geometry>
        <surface>
          <friction>
            <ode>
              <mu>1</mu>
              <mu2>1</mu2>
              <slip1>0.5</slip1>
              <slip2>0</slip2>
            </ode>
          </friction>
        </surface>
      </collision>
      <visual name="visual">
        <geometry>
         	        <mesh filename="package://robotMeshes/meshes/wheel.dae"/>
         </geometry>
      </visual>
    </link>

    <link name="left_rear_wheel">
      <pose>-0.125 0.201 -0.06 1.5707 0 0</pose>
      <collision name="collision">
        <geometry>
          <cylinder>
            <radius>0.110</radius>
            <length>0.075</length>
          </cylinder>
        </geometry>
        <surface>
          <friction>
            <ode>
              <mu>1</mu>
              <mu2>1</mu2>
              <slip1>0.5</slip1>
              <slip2>0</slip2>
            </ode>
          </friction>
        </surface>
      </collision>
      <visual name="visual">
        <geometry>
         	        <mesh filename="package://robotMeshes/meshes/wheel.dae"/>
        </geometry>
      </visual>
    </link>


    <joint type="revolute" name="right_front">
      <pose>0 0 0 0 0 0</pose>
      <child>right_front_wheel</child>
      <parent>base_link</parent>
      <axis>
        <xyz>0 1 0</xyz>
      </axis>
    </joint>
    <joint type="revolute" name="right_rear">
      <pose>0 0 0 0 0 0</pose>
      <child>right_rear_wheel</child>
      <parent>base_link</parent>
      <axis>
        <xyz>0 1 0</xyz>
      </axis>
    </joint>
    <joint type="revolute" name="left_front">
      <pose>0 0 0 0 0 0</pose>
      <child>left_front_wheel</child>
      <parent>base_link</parent>
      <axis>
        <xyz>0 1 0</xyz>
      </axis>
    </joint>
    <joint type="revolute" name="left_rear">
      <pose>0 0 0 0 0 0</pose>
      <child>left_rear_wheel</child>
      <parent>base_link</parent>
      <axis>
        <xyz>0 1 0</xyz>
      </axis>
    </joint>


  <joint name="hokuyo_joint" type="fixed">
    <axis xyz="0 1 0" />
    <origin xyz="0.15 0 0.037" rpy="0 0 0"/>
    <parent link="top_plate"/>
    <child link="hokuyo_link"/>
  </joint>

  <!-- Hokuyo Laser -->
  <link name="hokuyo_link">
    <collision>
      <origin xyz="0 0 0" rpy="0 0 0"/>
      <geometry>
    <box size="0.1 0.1 0.1"/>
      </geometry>
    </collision>

    <visual>
      <origin xyz="0 0 0" rpy="0 0 0"/> 
      <geometry>
        <mesh filename="package://robotMeshes/meshes/hokuyo1.dae"/>
      </geometry>

         </visual>

    <inertial>
      <mass value="1e-5" />
      <origin xyz="0 0 0" rpy="0 0 0"/>
      <inertia ixx="1e-6" ixy="0" ixz="0" iyy="1e-6" iyz="0" izz="1e-6" />
    </inertial>
  </link>

</robot>
